<sdf version='1.11'>
  <model name='nemo_auv'>
    <link name='base_link'>
      <inertial>
        <pose>0 0 -0.14999999999999999 0 0 0</pose>
        <mass>16.655336950308019</mass>
        <inertia>
          <ixx>0.31520658221610343</ixx>
          <ixy>0.0001</ixy>
          <ixz>0.0001</ixz>
          <iyy>0.56124681302340984</iyy>
          <iyz>0.0001</iyz>
          <izz>0.59765891176387809</izz>
        </inertia>
      </inertial>
      <collision name='base_link_collision'>
        <pose>0 0 0 0 0 0</pose>
        <geometry>
          <box>
            <size>0.65000000000000002 0.40000000000000002 0.40000000000000002</size>
          </box>
        </geometry>
      </collision>
      <visual name='base_link_visual'>
        <pose>0 0 0 0 0 0</pose>
        <geometry>
          <mesh>
            <scale>1 1 1</scale>
            <uri>model://nemo_description/meshes/visual_base_link.dae</uri>
          </mesh>
        </geometry>
      </visual>
    </link>
    <joint name='thruster1' type='revolute'>
      <pose relative_to='base_link'>0.2137 -0.092619999999999994 -0.078770000000000007 -1.7021285830697632e-10 1.5707960013486237 0.78499999988792324</pose>
      <parent>base_link</parent>
      <child>nemo_auv/thruster1</child>
      <axis>
        <xyz>0 0 1</xyz>
        <limit>
          <lower>-inf</lower>
          <upper>inf</upper>
        </limit>
        <dynamics>
          <spring_reference>0</spring_reference>
          <spring_stiffness>0</spring_stiffness>
        </dynamics>
      </axis>
    </joint>
    <link name='nemo_auv/thruster1'>
      <pose relative_to='thruster1'>0 0 0 0 0 0</pose>
      <inertial>
        <pose>0 0 0 0 0 0</pose>
        <mass>0.010685972005449421</mass>
        <inertia>
          <ixx>4.7097015385100217e-06</ixx>
          <ixy>0</ixy>
          <ixz>0</ixz>
          <iyy>4.7097015385085851e-06</iyy>
          <iyz>0</iyz>
          <izz>3.4241492607216479e-06</izz>
        </inertia>
      </inertial>
      <visual name='nemo_auv/thruster1_visual'>
        <pose>0 0 0 0 0 0</pose>
        <geometry>
          <mesh>
            <scale>1 1 1</scale>
            <uri>model://nemo_description/meshes/cwp.dae</uri>
          </mesh>
        </geometry>
      </visual>
    </link>
    <joint name='thruster2' type='revolute'>
      <pose relative_to='base_link'>0.2137 0.090529999999999999 -0.078770000000000007 1.7021285830697632e-10 1.5707960013486237 -0.78499999988792324</pose>
      <parent>base_link</parent>
      <child>nemo_auv/thruster2</child>
      <axis>
        <xyz>0 0 1</xyz>
        <limit>
          <lower>-inf</lower>
          <upper>inf</upper>
        </limit>
        <dynamics>
          <spring_reference>0</spring_reference>
          <spring_stiffness>0</spring_stiffness>
        </dynamics>
      </axis>
    </joint>
    <link name='nemo_auv/thruster2'>
      <pose relative_to='thruster2'>0 0 0 0 0 0</pose>
      <inertial>
        <pose>0 0 0 0 0 0</pose>
        <mass>0.010685972005449421</mass>
        <inertia>
          <ixx>4.7097015385100217e-06</ixx>
          <ixy>0</ixy>
          <ixz>0</ixz>
          <iyy>4.7097015385085851e-06</iyy>
          <iyz>0</iyz>
          <izz>3.4241492607216479e-06</izz>
        </inertia>
      </inertial>
      <visual name='nemo_auv/thruster2_visual'>
        <pose>0 0 0 0 0 0</pose>
        <geometry>
          <mesh>
            <scale>1 1 1</scale>
            <uri>model://nemo_description/meshes/cwp.dae</uri>
          </mesh>
        </geometry>
      </visual>
    </link>
    <joint name='thruster3' type='revolute'>
      <pose relative_to='base_link'>-0.21565999999999999 -0.092619999999999994 -0.078780000000000003 -1.7003546093788747e-10 1.57079600066706 2.3561940000014765</pose>
      <parent>base_link</parent>
      <child>nemo_auv/thruster3</child>
      <axis>
        <xyz>0 0 -1</xyz>
        <limit>
          <lower>-inf</lower>
          <upper>inf</upper>
        </limit>
        <dynamics>
          <spring_reference>0</spring_reference>
          <spring_stiffness>0</spring_stiffness>
        </dynamics>
      </axis>
    </joint>
    <link name='nemo_auv/thruster3'>
      <pose relative_to='thruster3'>0 0 0 0 0 0</pose>
      <inertial>
        <pose>0 0 0 0 0 0</pose>
        <mass>0.010685972005449421</mass>
        <inertia>
          <ixx>4.7097015385100217e-06</ixx>
          <ixy>0</ixy>
          <ixz>0</ixz>
          <iyy>4.7097015385085851e-06</iyy>
          <iyz>0</iyz>
          <izz>3.4241492607216479e-06</izz>
        </inertia>
      </inertial>
      <visual name='nemo_auv/thruster3_visual'>
        <pose>0 0 0 0 0 0</pose>
        <geometry>
          <mesh>
            <scale>1 1 1</scale>
            <uri>model://nemo_description/meshes/ccwp.dae</uri>
          </mesh>
        </geometry>
      </visual>
    </link>
    <joint name='thruster4' type='revolute'>
      <pose relative_to='base_link'>-0.21565999999999999 0.090529999999999999 -0.078780000000000003 1.7003546093788747e-10 1.57079600066706 -2.3561940000014765</pose>
      <parent>base_link</parent>
      <child>nemo_auv/thruster4</child>
      <axis>
        <xyz>0 0 -1</xyz>
        <limit>
          <lower>-inf</lower>
          <upper>inf</upper>
        </limit>
        <dynamics>
          <spring_reference>0</spring_reference>
          <spring_stiffness>0</spring_stiffness>
        </dynamics>
      </axis>
    </joint>
    <link name='nemo_auv/thruster4'>
      <pose relative_to='thruster4'>0 0 0 0 0 0</pose>
      <inertial>
        <pose>0 0 0 0 0 0</pose>
        <mass>0.010685972005449421</mass>
        <inertia>
          <ixx>4.7097015385100217e-06</ixx>
          <ixy>0</ixy>
          <ixz>0</ixz>
          <iyy>4.7097015385085851e-06</iyy>
          <iyz>0</iyz>
          <izz>3.4241492607216479e-06</izz>
        </inertia>
      </inertial>
      <visual name='nemo_auv/thruster4_visual'>
        <pose>0 0 0 0 0 0</pose>
        <geometry>
          <mesh>
            <scale>1 1 1</scale>
            <uri>model://nemo_description/meshes/ccwp.dae</uri>
          </mesh>
        </geometry>
      </visual>
    </link>
    <joint name='thruster5' type='revolute'>
      <pose relative_to='base_link'>0.14902000000000001 -0.23605000000000001 0.00012300000000000001 0 0 0</pose>
      <parent>base_link</parent>
      <child>nemo_auv/thruster5</child>
      <axis>
        <xyz>0 0 1</xyz>
        <limit>
          <lower>-inf</lower>
          <upper>inf</upper>
        </limit>
        <dynamics>
          <spring_reference>0</spring_reference>
          <spring_stiffness>0</spring_stiffness>
        </dynamics>
      </axis>
    </joint>
    <link name='nemo_auv/thruster5'>
      <pose relative_to='thruster5'>0 0 0 0 0 0</pose>
      <inertial>
        <pose>0 0 0 0 0 0</pose>
        <mass>0.010685972005449421</mass>
        <inertia>
          <ixx>4.7097015385100217e-06</ixx>
          <ixy>0</ixy>
          <ixz>0</ixz>
          <iyy>4.7097015385085851e-06</iyy>
          <iyz>0</iyz>
          <izz>3.4241492607216479e-06</izz>
        </inertia>
      </inertial>
      <visual name='nemo_auv/thruster5_visual'>
        <pose>0 0 0 0 0 0</pose>
        <geometry>
          <mesh>
            <scale>1 1 1</scale>
            <uri>model://nemo_description/meshes/cwp.dae</uri>
          </mesh>
        </geometry>
      </visual>
    </link>
    <joint name='thruster6' type='revolute'>
      <pose relative_to='base_link'>0.14902000000000001 0.23394999999999999 0.00012300000000000001 0 0 0</pose>
      <parent>base_link</parent>
      <child>nemo_auv/thruster6</child>
      <axis>
        <xyz>0 0 -1</xyz>
        <limit>
          <lower>-inf</lower>
          <upper>inf</upper>
        </limit>
        <dynamics>
          <spring_reference>0</spring_reference>
          <spring_stiffness>0</spring_stiffness>
        </dynamics>
      </axis>
    </joint>
    <link name='nemo_auv/thruster6'>
      <pose relative_to='thruster6'>0 0 0 0 0 0</pose>
      <inertial>
        <pose>0 0 0 0 0 0</pose>
        <mass>0.010685972005449421</mass>
        <inertia>
          <ixx>4.7097015385100217e-06</ixx>
          <ixy>0</ixy>
          <ixz>0</ixz>
          <iyy>4.7097015385085851e-06</iyy>
          <iyz>0</iyz>
          <izz>3.4241492607216479e-06</izz>
        </inertia>
      </inertial>
      <visual name='nemo_auv/thruster6_visual'>
        <pose>0 0 0 0 0 0</pose>
        <geometry>
          <mesh>
            <scale>1 1 1</scale>
            <uri>model://nemo_description/meshes/ccwp.dae</uri>
          </mesh>
        </geometry>
      </visual>
    </link>
    <joint name='thruster7' type='revolute'>
      <pose relative_to='base_link'>-0.15098 -0.23605000000000001 0.00012300000000000001 0 0 0</pose>
      <parent>base_link</parent>
      <child>nemo_auv/thruster7</child>
      <axis>
        <xyz>0 0 -1</xyz>
        <limit>
          <lower>-inf</lower>
          <upper>inf</upper>
        </limit>
        <dynamics>
          <spring_reference>0</spring_reference>
          <spring_stiffness>0</spring_stiffness>
        </dynamics>
      </axis>
    </joint>
    <link name='nemo_auv/thruster7'>
      <pose relative_to='thruster7'>0 0 0 0 0 0</pose>
      <inertial>
        <pose>0 0 0 0 0 0</pose>
        <mass>0.010685972005449421</mass>
        <inertia>
          <ixx>4.7097015385100217e-06</ixx>
          <ixy>0</ixy>
          <ixz>0</ixz>
          <iyy>4.7097015385085851e-06</iyy>
          <iyz>0</iyz>
          <izz>3.4241492607216479e-06</izz>
        </inertia>
      </inertial>
      <visual name='nemo_auv/thruster7_visual'>
        <pose>0 0 0 0 0 0</pose>
        <geometry>
          <mesh>
            <scale>1 1 1</scale>
            <uri>model://nemo_description/meshes/ccwp.dae</uri>
          </mesh>
        </geometry>
      </visual>
    </link>
    <joint name='thruster8' type='revolute'>
      <pose relative_to='base_link'>-0.15098 0.23394999999999999 0.00012300000000000001 0 0 0</pose>
      <parent>base_link</parent>
      <child>nemo_auv/thruster8</child>
      <axis>
        <xyz>0 0 1</xyz>
        <limit>
          <lower>-inf</lower>
          <upper>inf</upper>
        </limit>
        <dynamics>
          <spring_reference>0</spring_reference>
          <spring_stiffness>0</spring_stiffness>
        </dynamics>
      </axis>
    </joint>
    <link name='nemo_auv/thruster8'>
      <pose relative_to='thruster8'>0 0 0 0 0 0</pose>
      <inertial>
        <pose>0 0 0 0 0 0</pose>
        <mass>0.010685972005449421</mass>
        <inertia>
          <ixx>4.7097015385100217e-06</ixx>
          <ixy>0</ixy>
          <ixz>0</ixz>
          <iyy>4.7097015385085851e-06</iyy>
          <iyz>0</iyz>
          <izz>3.4241492607216479e-06</izz>
        </inertia>
      </inertial>
      <visual name='nemo_auv/thruster8_visual'>
        <pose>0 0 0 0 0 0</pose>
        <geometry>
          <mesh>
            <scale>1 1 1</scale>
            <uri>model://nemo_description/meshes/cwp.dae</uri>
          </mesh>
        </geometry>
      </visual>
    </link>
    <plugin name='gz::sim::systems::Hydrodynamics' filename='gz-sim-hydrodynamics-system'>
      <link_name>base_link</link_name>
      <xDotU>-5.5</xDotU>
      <yDotV>-12.7</yDotV>
      <zDotW>-14.57</zDotW>
      <kDotP>-0.12</kDotP>
      <mDotQ>-0.12</mDotQ>
      <nDotR>-0.12</nDotR>
      <xUabsU>-33.800000000000004</xUabsU>
      <yVabsV>-54.26875</yVabsV>
      <zWabsW>-73.37135</zWabsW>
      <kPabsP>-40.0</kPabsP>
      <mQabsQ>-40.0</mQabsQ>
      <nRabsR>-40.0</nRabsR>
      <xU>-25.15</xU>
      <yV>-7.364</yV>
      <zW>-17.955</zW>
      <kP>-10.888</kP>
      <mQ>-20.761</mQ>
      <nR>-3.744</nR>
    </plugin>
    <plugin name='gz::sim::systems::Thruster' filename='gz-sim-thruster-system'>
      <namespace>nemo_auv</namespace>
      <joint_name>thruster1</joint_name>
      <topic>thruster1/cmd</topic>
      <thrust_coefficient>0.011</thrust_coefficient>
      <fluid_density>1000</fluid_density>
      <propeller_diameter>0.090</propeller_diameter>
      <velocity_control>false</velocity_control>
      <use_angvel_cmd>true</use_angvel_cmd>
      <max_thrust_cmd>335</max_thrust_cmd>
      <min_thrust_cmd>-335</min_thrust_cmd>
    </plugin>
    <plugin name='gz::sim::systems::Thruster' filename='gz-sim-thruster-system'>
      <namespace>nemo_auv</namespace>
      <joint_name>thruster2</joint_name>
      <topic>thruster2/cmd</topic>
      <thrust_coefficient>0.011</thrust_coefficient>
      <fluid_density>1000</fluid_density>
      <propeller_diameter>0.090</propeller_diameter>
      <velocity_control>false</velocity_control>
      <use_angvel_cmd>true</use_angvel_cmd>
      <max_thrust_cmd>335</max_thrust_cmd>
      <min_thrust_cmd>-335</min_thrust_cmd>
    </plugin>
    <plugin name='gz::sim::systems::Thruster' filename='gz-sim-thruster-system'>
      <namespace>nemo_auv</namespace>
      <joint_name>thruster5</joint_name>
      <topic>thruster5/cmd</topic>
      <thrust_coefficient>0.011</thrust_coefficient>
      <fluid_density>1000</fluid_density>
      <propeller_diameter>0.090</propeller_diameter>
      <velocity_control>false</velocity_control>
      <use_angvel_cmd>true</use_angvel_cmd>
      <max_thrust_cmd>335</max_thrust_cmd>
      <min_thrust_cmd>-335</min_thrust_cmd>
    </plugin>
    <plugin name='gz::sim::systems::Thruster' filename='gz-sim-thruster-system'>
      <namespace>nemo_auv</namespace>
      <joint_name>thruster8</joint_name>
      <topic>thruster8/cmd</topic>
      <thrust_coefficient>0.011</thrust_coefficient>
      <fluid_density>1000</fluid_density>
      <propeller_diameter>0.090</propeller_diameter>
      <velocity_control>false</velocity_control>
      <use_angvel_cmd>true</use_angvel_cmd>
      <max_thrust_cmd>335</max_thrust_cmd>
      <min_thrust_cmd>-335</min_thrust_cmd>
    </plugin>
    <plugin name='gz::sim::systems::Thruster' filename='gz-sim-thruster-system'>
      <namespace>nemo_auv</namespace>
      <joint_name>thruster3</joint_name>
      <topic>thruster3/cmd</topic>
      <thrust_coefficient>0.011</thrust_coefficient>
      <fluid_density>1000</fluid_density>
      <propeller_diameter>0.090</propeller_diameter>
      <velocity_control>false</velocity_control>
      <use_angvel_cmd>True</use_angvel_cmd>
      <max_thrust_cmd>335</max_thrust_cmd>
      <min_thrust_cmd>-335</min_thrust_cmd>
    </plugin>
    <plugin name='gz::sim::systems::Thruster' filename='gz-sim-thruster-system'>
      <namespace>nemo_auv</namespace>
      <joint_name>thruster4</joint_name>
      <topic>thruster4/cmd</topic>
      <thrust_coefficient>0.011</thrust_coefficient>
      <fluid_density>1000</fluid_density>
      <propeller_diameter>0.090</propeller_diameter>
      <velocity_control>false</velocity_control>
      <use_angvel_cmd>True</use_angvel_cmd>
      <max_thrust_cmd>335</max_thrust_cmd>
      <min_thrust_cmd>-335</min_thrust_cmd>
    </plugin>
    <plugin name='gz::sim::systems::Thruster' filename='gz-sim-thruster-system'>
      <namespace>nemo_auv</namespace>
      <joint_name>thruster6</joint_name>
      <topic>thruster6/cmd</topic>
      <thrust_coefficient>0.011</thrust_coefficient>
      <fluid_density>1000</fluid_density>
      <propeller_diameter>0.090</propeller_diameter>
      <velocity_control>false</velocity_control>
      <use_angvel_cmd>True</use_angvel_cmd>
      <max_thrust_cmd>335</max_thrust_cmd>
      <min_thrust_cmd>-335</min_thrust_cmd>
    </plugin>
    <plugin name='gz::sim::systems::Thruster' filename='gz-sim-thruster-system'>
      <namespace>nemo_auv</namespace>
      <joint_name>thruster7</joint_name>
      <topic>thruster7/cmd</topic>
      <thrust_coefficient>0.011</thrust_coefficient>
      <fluid_density>1000</fluid_density>
      <propeller_diameter>0.090</propeller_diameter>
      <velocity_control>false</velocity_control>
      <use_angvel_cmd>True</use_angvel_cmd>
      <max_thrust_cmd>335</max_thrust_cmd>
      <min_thrust_cmd>-335</min_thrust_cmd>
    </plugin>
  </model>
</sdf>
